# **예외 처리**
## **1. Exception**
### **1.1 개요**
예외 처리란 말 그대로 **어떠한 예외 사항이 발생했을 때를 대비하여 미리 예측하고 처리**하는 것을 뜻한다.

프로그래밍 언어마다 예외처리의 방법이 조금씩 다른데, 자바에서는 **try-catch-finally**문을 사용한다.
### **1.2 컴파일 오류와 예외**
컴파일 오류와 예외는 겉으로 보기에는 비슷하나, 차이점이 존재한다.
|**컴파일 오류**|**예외**|
|:-:|:-:|
|문법이 맞지 않아 발생하는 오류|여러 상황에서 잘못된 값으로 발생하는 예기치 못한 사건|
### **1.3. 사용 방법**
예외 처리시 사용하는 try-catch-finally문의 사용법은 다음과 같다.
```java
try{
    ...
}catch(Exception_Name){
    ...
}finally{
    ...
}
```
먼저 try 블록에서 예외 발생이 예상되는 코드를 넣는다. 만약, **try 블록 내에서 예외가 발생하면 그 이후로의 코드는 실행되지 않는다.**

다음으로 catch 블록에서 **선언한 예외와 일치**하면 catch 블록 안에 있는 코드가 실행된다.

마지막으로 finally 블록 안에 있는 코드가 **예외 발생 여부와 상관없이 반드시** 실행된다. (finally문은 생략 가능하다.)

만약 **모든 예외를 처리**하고자 한다면 **Exception 클래스를 이용**해 코드를 작성한다. 이는 모든 예외 객체가 Exception 클래스를 상속받는 것을 이용한 것이다.
```java
catch(Exception e){
    ...
}
```
### **1.4 코드 예시**
다음 코드는 try문에서 0으로 나누는 예외사항인 ArithmeticException을 일으킨다.
```java
public class ExceptionExam {

	public static void main(String[] args) {
		int i = 10;
		int j = 0;
		try {
			int k = i/j; // j = 0 이므로 예외 발생
			System.out.println(k);
		}catch(ArithmeticException e) {
			System.out.println("cannot divide by zero " + e.toString());
		}finally {
			System.out.println("finally is progressed."); //예외 발생 여부와 상관없이 무조건 실행
        }
		System.out.println("main end!");
	}

}
```
_실행결과: cannot divide by zero java.lang.ArithmeticException: / by zero
finally is progressed.
main end!_

위 코드에서 **참조변수 e는 ArithmeticException이라는 예외 객체를 참조**한다.

그리고  toString 메서드는 예외정보를 나타낸다.

finally 안의 코드들은 try-catch문에서 예외 처리가 제대로 안됐다고 해도 무조건 실행시킨다.
```java
public class ExceptionExam {

	public static void main(String[] args) {
		int i = 10;
		int j = 0;
		try {
			int k = i/j; // j = 0 이므로 예외 발생
			System.out.println(k);
		}catch(NullPointerException e) {
			System.out.println("Null cannot be handled " + e.toString());
		}finally {
			System.out.println("finally is progressed."); //예외 발생 여부와 상관없이 무조건 실행
        }
		System.out.println("main end!");
	}

}
```
_실행결과: finally is progressed.
Exception in thread "main" java.lang.ArithmeticException: / by zero
	at Exception.ExceptionExam2.main(ExceptionExam2.java:9)_
## **2. Throws**
### **2.1. 개요**
Exception 에서는 try-catch-finally문을 이용하여 직접 해당 구간에서 예외 처리를 하였다. 이외에도 **호출한 쪽으로 예외를 넘기는 키워드**인 **throws**를 사용할 수도 있다.
### **2.2. 사용 방법**
throws는 다음과 같이 사용한다.
```java
Class throws Exception_Name{
    ...
}
```
Exception_Name에는 특정 예외 뿐만 아니라, catch문처럼 Exception을 통해 모든 예외를 넘길 수 있다.
### **2.3 코드 예시**
다음은 메서드를 호출한 곳에서 예외 처리하는 코드이다.
```java
public class ExceptionExam3 {

	public static void main(String[] args) {
		int i = 10;
		int j = 0;
		try {
			int k = divide(i, j);
			System.out.println(k);
		}catch(Exception e){
			System.out.println(e.toString());
		}
	}
	public static int divide(int i, int j) throws ArithmeticException{
		int k = i/j;
		return k;
	}

}
```
_실행결과: java.lang.ArithmeticException: / by zero_
## **3. Exception 발생시키기 (throw)**
### **3.1. 개요**
throw 키워드는 **강제로 오류를 발생**시키며, 주로 throws 키워드와 같이 사용한다.

throw 키워드는 **해당 키워드가 들어간 라인에서 Exception이 발생한다**는 의미이다.
### **3.2. 사용방법**
이 키워드는 주로 프로그래머가 원치 않는 상황을 방지하기 위해 일부러 Exception을 발생시켜야 할때 사용된다.
```java
//details안에 추가 사항을 넣을 수도 있다. (생략가능)
throw new Exception_Name(details);
```
new 키워드로 예외 객체를 만들고 throw 키워드로 예외 객체를 발생시킨다.
### **3.3. 코드 예시**
```java
public class ExceptionExam4 {

	public static void main(String[] args) {
		int i = 10;
		int j = 0;
		try {
			int k = divide(i, j);
			System.out.println(k);
		}catch(IllegalArgumentException e) {
			System.out.println(e.toString());
		}
	}
	public static int divide(int i, int j) throws IllegalArgumentException{
		if(j == 0) {
			throw new IllegalArgumentException("cannot divide by zero.");
		}
		int k = i/j;
		return k;
	}
}
```
## **4. 사용자 정의 Exception**
### **4.1 개요**
자바에는 이미 정의된 여러 예외가 있지만, 사용자가 직접 정의해서 사용할 수도 있다.

이러한 사용자 정의 예외를 만드는 이유는 **사용자에게 직관적으로 알려주기 위함**이다.
### **4.2 선언법**
새로운 예외 선언법은 2가지가 있다.

* Exception을 상속받음
```java
public class Class_Name extends Exception{
    ...
}
```
여기서 새롭게 만든 예외를 **Checked Exception**이라고 한다.

Checked Exception은 처리를 해주지 않으면 컴파일 에러가 발생한다. 

* RuntimeException을 상속받음
```java
public class Class_Name extends RuntimeException{
    ...
}
```
RuntimeException을 상속받은 예외(= unChecked Exception)는 에러 처리를 안해도된다.
### **4.3. 코드 예시**
먼저, BizException 객체를 정의한다.
```java
public class BizException extends RuntimeException {
    //msg를 가져와 super에 보내는 생성자
	public BizException(String msg) {
		super(msg);
	}
    //Exception을 받아들여 super에 넘기는 생성자
	public BizException(Exception ex) {
		super(ex);
	}
	
}
```
예외 객체는 보통 생성자만 포함하나, 필드 및 메서드도 포함할 수 있다.

위 코드에서는 생성자 BizException만 포함했다.

부모 클래스인 RuntimeException에 이미 같은 기능을 하는 생성자가 있으므로, 전달만 해준다.
```java
public class BizService {
	public void bizMethod(int i) throws BizException{
		System.out.println("Business Method is started..");
		if(i < 0)
			throw new BizException("The parameter i should be greater than zero.");
		System.out.println("Business Method is ended.");
	}
}
```
```java
public class BizExam {

	public static void main(String[] args) {
		BizService biz = new BizService();
		biz.bizMethod(5);
		try {
			biz.bizMethod(-3);
		}catch(Exception e) {
			e.printStackTrace();
		}
		System.out.println("closing programs..");

	}

}
```
### **4.4. Checked Exception과 unChecked Exception**
이 둘의 차이점은 **컴파일 시에 컴파일 에러를 발생시켜서 반드시 에러를 처리할지**에 대한 여부이다.